<?xml version="1.0" encoding="utf-8"?>
<!-- This URDF was automatically created by SolidWorks to URDF Exporter! Originally created by Stephen Brawner (brawner@gmail.com) 
     Commit Version: 1.6.0-4-g7f85cfe  Build Version: 1.6.7995.38578
     For more information, please see http://wiki.ros.org/sw_urdf_exporter -->
<robot
  name="mobiman/urdf/R1_PRO">
  <link
    name="torso_link4">
    <inertial>
      <origin
        xyz="0.00011729 -1.0769E-07 0.17437"
        rpy="0 0 0" />
      <mass
        value="13.013" />
      <inertia
        ixx="0.0036183"
        ixy="2.8169E-08"
        ixz="-7.6865E-10"
        iyy="0.0038564"
        iyz="-3.8309E-07"
        izz="0.0040336" />
    </inertial>
    <visual>
      <origin
        xyz="0 0 0"
        rpy="0 0 0" />
      <geometry>
        <mesh
          filename="package://mobiman/urdf/R1_PRO/meshes/torso_link4.STL" />
      </geometry>
      <material
        name="">
        <color
          rgba="0.82353 0.82353 1 1" />
      </material>
    </visual>
    <collision>
      <origin
        xyz="0 0 0"
        rpy="0 0 0" />
      <geometry>
        <mesh
          filename="package://mobiman/urdf/R1_PRO/meshes/torso_link4.STL" />
      </geometry>
    </collision>
  </link>
  <link
    name="zed_link">
    <inertial>
      <origin
        xyz="-0.068413 -0.060004 -0.015906"
        rpy="0 0 0" />
      <mass
        value="2.08" />
      <inertia
        ixx="0.012229"
        ixy="-1.333E-08"
        ixz="-0.00028961"
        iyy="0.010375"
        iyz="1.8965E-07"
        izz="0.014618" />
    </inertial>
    <visual>
      <origin
        xyz="0 0 0"
        rpy="0 0 0" />
      <geometry>
        <mesh
          filename="package://mobiman/urdf/R1_PRO/meshes/zed_link.STL" />
      </geometry>
      <material
        name="">
        <color
          rgba="0.81176 0.84314 0.9098 1" />
      </material>
    </visual>
    <collision>
      <origin
        xyz="0 0 0"
        rpy="0 0 0" />
      <geometry>
        <mesh
          filename="package://mobiman/urdf/R1_PRO/meshes/zed_link.STL" />
      </geometry>
    </collision>
  </link>
  <joint
    name="zed_joint"
    type="fixed">
    <origin
      xyz="0.0655115038230265 0.0600050181066706 0.47598409534027"
      rpy="0 0.349063929519474 0" />
    <parent
      link="torso_link4" />
    <child
      link="zed_link" />
    <axis
      xyz="0 0 0" />
  </joint>
  <link
    name="left_arm_link1">
    <inertial>
      <origin
        xyz="0.0032166 0.10591 0.00"
        rpy="0 0 0" />
      <mass
        value="1.319" />
      <inertia
        ixx="0.0017994"
        ixy="0.00041828"
        ixz="0.0013358"
        iyy="0.0018519"
        iyz="-0.0067019"
        izz="0.0050487" />
    </inertial>
    <visual>
      <origin
        xyz="0 0 0"
        rpy="0 0 0" />
      <geometry>
        <mesh
          filename="package://mobiman/urdf/R1_PRO/meshes/left_arm_link1.STL" />
      </geometry>
      <material
        name="">
        <color
          rgba="0.79216 0.81961 0.93333 1" />
      </material>
    </visual>
    <collision>
      <origin
        xyz="0 0 0"
        rpy="0 0 0" />
      <geometry>
        <mesh
          filename="package://mobiman/urdf/R1_PRO/meshes/left_arm_link1.STL" />
      </geometry>
    </collision>
  </link>
  <joint
    name="left_arm_joint1"
    type="revolute">
    <origin
      xyz="-0.00033792 0.13608 0.30285"
      rpy="0 0 0" />
    <parent
      link="torso_link4" />
    <child
      link="left_arm_link1" />
    <axis
      xyz="0 1 0" />
    <limit
      lower="-2.8798"
      upper="2.8798"
      effort="40"
      velocity="20.944" />
  </joint>
  <link
    name="left_arm_link2">
    <inertial>
      <origin
        xyz="-0.23622 0.016352 -0.00013275"
        rpy="0 0 0" />
      <mass
        value="1.3" />
      <inertia
        ixx="0.00060638"
        ixy="0.00041817"
        ixz="0.00014956"
        iyy="0.0075936"
        iyz="-8.0916E-06"
        izz="0.0075712" />
    </inertial>
    <visual>
      <origin
        xyz="0 0 0"
        rpy="0 0 0" />
      <geometry>
        <mesh
          filename="package://mobiman/urdf/R1_PRO/meshes/left_arm_link2.STL" />
      </geometry>
      <material
        name="">
        <color
          rgba="0.79216 0.81961 0.93333 1" />
      </material>
    </visual>
    <collision>
      <origin
        xyz="0 0 0"
        rpy="0 0 0" />
      <geometry>
        <mesh
          filename="package://mobiman/urdf/R1_PRO/meshes/left_arm_link2.STL" />
      </geometry>
    </collision>
  </link>
  <joint
    name="left_arm_joint2"
    type="revolute">
    <origin
      xyz="0 0.11185 0"
      rpy="0 0 0" />
    <parent
      link="left_arm_link1" />
    <child
      link="left_arm_link2" />
    <axis
      xyz="0 0 -1" />
    <limit
      lower="0"
      upper="3.2289"
      effort="40"
      velocity="20.944" />
  </joint>
  <link
    name="left_arm_link3">
    <inertial>
      <origin
        xyz="0.045114 0.054616 -0.00045593"
        rpy="0 0 0" />
      <mass
        value="0.818" />
      <inertia
        ixx="0.00060107"
        ixy="-0.00022467"
        ixz="-7.1194E-06"
        iyy="0.0013959"
        iyz="-9.7503E-06"
        izz="0.0015027" />
    </inertial>
    <visual>
      <origin
        xyz="0 0 0"
        rpy="0 0 0" />
      <geometry>
        <mesh
          filename="package://mobiman/urdf/R1_PRO/meshes/left_arm_link3.STL" />
      </geometry>
      <material
        name="">
        <color
          rgba="0.79216 0.81961 0.93333 1" />
      </material>
    </visual>
    <collision>
      <origin
        xyz="0 0 0"
        rpy="0 0 0" />
      <geometry>
        <mesh
          filename="package://mobiman/urdf/R1_PRO/meshes/left_arm_link3.STL" />
      </geometry>
    </collision>
  </link>
  <joint
    name="left_arm_joint3"
    type="revolute">
    <origin
      xyz="-0.34928 0.019998 0"
      rpy="0 0 0" />
    <parent
      link="left_arm_link2" />
    <child
      link="left_arm_link3" />
    <axis
      xyz="0 0 -1" />
    <limit
      lower="-3.3161"
      upper="0"
      effort="27"
      velocity="7.5389" />
  </joint>
  <link
    name="left_arm_link4">
    <inertial>
      <origin
        xyz="0.24285 0.0023784 1.279E-06"
        rpy="0 0 0" />
      <mass
        value="0.816" />
      <inertia
        ixx="8.45E-05"
        ixy="-8.2627E-07"
        ixz="-2.2607E-09"
        iyy="0.00010174"
        iyz="5.3612E-09"
        izz="9.7044E-05" />
    </inertial>
    <visual>
      <origin
        xyz="0 0 0"
        rpy="0 0 0" />
      <geometry>
        <mesh
          filename="package://mobiman/urdf/R1_PRO/meshes/left_arm_link4.STL" />
      </geometry>
      <material
        name="">
        <color
          rgba="1 1 1 1" />
      </material>
    </visual>
    <collision>
      <origin
        xyz="0 0 0"
        rpy="0 0 0" />
      <geometry>
        <mesh
          filename="package://mobiman/urdf/R1_PRO/meshes/left_arm_link4.STL" />
      </geometry>
    </collision>
  </link>
  <joint
    name="left_arm_joint4"
    type="revolute">
    <origin
      xyz="0.02735 0.069767 0"
      rpy="0 0 0" />
    <parent
      link="left_arm_link3" />
    <child
      link="left_arm_link4" />
    <axis
      xyz="1 0 0" />
    <limit
      lower="-2.8798"
      upper="2.8798"
      effort="7"
      velocity="25.133" />
  </joint>
  <link
    name="left_arm_link5">
    <inertial>
      <origin
        xyz="0.054309 0.0041811 4.0699E-06"
        rpy="0 0 0" />
      <mass
        value="0.801" />
      <inertia
        ixx="8.3999E-05"
        ixy="1.6234E-05"
        ixz="7.4127E-08"
        iyy="9.8498E-05"
        iyz="-1.3811E-08"
        izz="0.00011333" />
    </inertial>
    <visual>
      <origin
        xyz="0 0 0"
        rpy="0 0 0" />
      <geometry>
        <mesh
          filename="package://mobiman/urdf/R1_PRO/meshes/left_arm_link5.STL" />
      </geometry>
      <material
        name="">
        <color
          rgba="1 1 1 1" />
      </material>
    </visual>
    <collision>
      <origin
        xyz="0 0 0"
        rpy="0 0 0" />
      <geometry>
        <mesh
          filename="package://mobiman/urdf/R1_PRO/meshes/left_arm_link5.STL" />
      </geometry>
    </collision>
  </link>
  <joint
    name="left_arm_joint5"
    type="revolute">
    <origin
      xyz="0.2463 -0.00049894 0"
      rpy="0 0 0" />
    <parent
      link="left_arm_link4" />
    <child
      link="left_arm_link5" />
    <axis
      xyz="0 1 0" />
    <limit
      lower="-1.6581"
      upper="1.6581"
      effort="7"
      velocity="25.133" />
  </joint>
  <link
    name="left_arm_link6">
    <inertial>
      <origin
        xyz="-0.031107 -1.3893E-07 -1.437E-07"
        rpy="0 0 0" />
      <mass
        value="0.465" />
      <inertia
        ixx="0.00017588"
        ixy="4.1789E-10"
        ixz="-5.3493E-10"
        iyy="9.8637E-05"
        iyz="-8.1856E-08"
        izz="0.00016512" />
    </inertial>
    <visual>
      <origin
        xyz="0 0 0"
        rpy="0 0 0" />
      <geometry>
        <mesh
          filename="package://mobiman/urdf/R1_PRO/meshes/left_arm_link6.STL" />
      </geometry>
      <material
        name="">
        <color
          rgba="0.82353 0.82353 1 1" />
      </material>
    </visual>
    <collision>
      <origin
        xyz="0 0 0"
        rpy="0 0 0" />
      <geometry>
        <mesh
          filename="package://mobiman/urdf/R1_PRO/meshes/left_arm_link6.STL" />
      </geometry>
    </collision>
  </link>
  <joint
    name="left_arm_joint6"
    type="revolute">
    <origin
      xyz="0.16215 0.0005007 0"
      rpy="0 0 0" />
    <parent
      link="left_arm_link5" />
    <child
      link="left_arm_link6" />
    <axis
      xyz="1 0 0" />
    <limit
      lower="-2.8798"
      upper="2.8798"
      effort="7"
      velocity="25.133" />
  </joint>
  <link
    name="left_realsense_link">
    <inertial>
      <origin
        xyz="-0.017353 -0.022169 -0.0060171"
        rpy="0 0 0" />
      <mass
        value="0.25" />
      <inertia
        ixx="2.5513E-05"
        ixy="-1.2797E-06"
        ixz="1.4268E-06"
        iyy="6.965E-06"
        iyz="2.6612E-06"
        izz="2.3281E-05" />
    </inertial>
    <visual>
      <origin
        xyz="0 0 0"
        rpy="0 0 0" />
      <geometry>
        <mesh
          filename="package://mobiman/urdf/R1_PRO/meshes/left_realsense_link.STL" />
      </geometry>
      <material
        name="">
        <color
          rgba="0.8 0.8 0.8 1" />
      </material>
    </visual>
    <collision>
      <origin
        xyz="0 0 0"
        rpy="0 0 0" />
      <geometry>
        <mesh
          filename="package://mobiman/urdf/R1_PRO/meshes/left_realsense_link.STL" />
      </geometry>
    </collision>
  </link>
  <joint
    name="left_realsense_joint"
    type="fixed">
    <origin
      xyz="-0.0051316 0.0021066 0.050549"
      rpy="0.0085876 0.43632 0.0036336" />
    <parent
      link="left_arm_link6" />
    <child
      link="left_realsense_link" />
    <axis
      xyz="0 0 0" />
  </joint>
  <link
    name="left_gripper_link1">
    <inertial>
      <origin
        xyz="-0.019589 -0.015114 0.0054225"
        rpy="0 0 0" />
      <mass
        value="0.057" />
      <inertia
        ixx="2.4057E-06"
        ixy="3.9897E-07"
        ixz="5.1206E-08"
        iyy="5.7108E-06"
        iyz="6.1948E-08"
        izz="6.4849E-06" />
    </inertial>
    <visual>
      <origin
        xyz="0 0 0"
        rpy="0 0 0" />
      <geometry>
        <mesh
          filename="package://mobiman/urdf/R1_PRO/meshes/left_gripper_link1.STL" />
      </geometry>
      <material
        name="">
        <color
          rgba="0.82353 0.82353 1 1" />
      </material>
    </visual>
    <collision>
      <origin
        xyz="0 0 0"
        rpy="0 0 0" />
      <geometry>
        <mesh
          filename="package://mobiman/urdf/R1_PRO/meshes/left_gripper_link1.STL" />
      </geometry>
    </collision>
  </link>
  <joint
    name="left_gripper_joint1"
    type="prismatic">
    <origin
      xyz="0.03689 0.013453 0.00012067"
      rpy="0 0 0" />
    <parent
      link="left_arm_link6" />
    <child
      link="left_gripper_link1" />
    <axis
      xyz="0 1 0" />
    <limit
      lower="0"
      upper="0.05"
      effort="100"
      velocity="0.25" />
  </joint>
  <link
    name="left_gripper_link2">
    <inertial>
      <origin
        xyz="-0.01959 0.015114 -0.0054226"
        rpy="0 0 0" />
      <mass
        value="0.057" />
      <inertia
        ixx="2.4057E-06"
        ixy="-3.99E-07"
        ixz="-5.1222E-08"
        iyy="5.7108E-06"
        iyz="6.1946E-08"
        izz="6.4849E-06" />
    </inertial>
    <visual>
      <origin
        xyz="0 0 0"
        rpy="0 0 0" />
      <geometry>
        <mesh
          filename="package://mobiman/urdf/R1_PRO/meshes/left_gripper_link2.STL" />
      </geometry>
      <material
        name="">
        <color
          rgba="0.82353 0.82353 1 1" />
      </material>
    </visual>
    <collision>
      <origin
        xyz="0 0 0"
        rpy="0 0 0" />
      <geometry>
        <mesh
          filename="package://mobiman/urdf/R1_PRO/meshes/left_gripper_link2.STL" />
      </geometry>
    </collision>
  </link>
  <joint
    name="left_gripper_joint2"
    type="prismatic">
    <origin
      xyz="0.03689 -0.013453 -0.00012053"
      rpy="0 0 0" />
    <parent
      link="left_arm_link6" />
    <child
      link="left_gripper_link2" />
    <axis
      xyz="0 -1 0" />
    <limit
      lower="0"
      upper="0.05"
      effort="100"
      velocity="0.25" />
  </joint>
  <link
    name="right_arm_link1">
    <inertial>
      <origin
        xyz="0.032165 -0.10201 -0.00933"
        rpy="0 0 0" />
      <mass
        value="1.319" />
      <inertia
        ixx="0.0017994"
        ixy="0.00041828"
        ixz="0.0013358"
        iyy="0.0018519"
        iyz="-0.0067019"
        izz="0.0050487" />
    </inertial>
    <visual>
      <origin
        xyz="0 0 0"
        rpy="0 0 0" />
      <geometry>
        <mesh
          filename="package://mobiman/urdf/R1_PRO/meshes/right_arm_link1.STL" />
      </geometry>
      <material
        name="">
        <color
          rgba="0.79216 0.81961 0.93333 1" />
      </material>
    </visual>
    <collision>
      <origin
        xyz="0 0 0"
        rpy="0 0 0" />
      <geometry>
        <mesh
          filename="package://mobiman/urdf/R1_PRO/meshes/right_arm_link1.STL" />
      </geometry>
    </collision>
  </link>
  <joint
    name="right_arm_joint1"
    type="revolute">
    <origin
      xyz="-0.00033672 -0.14184 0.30285"
      rpy="0 0 0" />
    <parent
      link="torso_link4" />
    <child
      link="right_arm_link1" />
    <axis
      xyz="0 -1 0" />
    <limit
      lower="-2.8798"
      upper="2.8798"
      effort="40"
      velocity="20.944" />
  </joint>
  <link
    name="right_arm_link2">
    <inertial>
      <origin
        xyz="-0.23622 -0.016354 0.00013183"
        rpy="0 0 0" />
      <mass
        value="1.3" />
      <inertia
        ixx="0.00060639"
        ixy="-0.00041823"
        ixz="-0.00014958"
        iyy="0.0075936"
        iyz="-8.0947E-06"
        izz="0.0075712" />
    </inertial>
    <visual>
      <origin
        xyz="0 0 0"
        rpy="0 0 0" />
      <geometry>
        <mesh
          filename="package://mobiman/urdf/R1_PRO/meshes/right_arm_link2.STL" />
      </geometry>
      <material
        name="">
        <color
          rgba="0.79216 0.81961 0.93333 1" />
      </material>
    </visual>
    <collision>
      <origin
        xyz="0 0 0"
        rpy="0 0 0" />
      <geometry>
        <mesh
          filename="package://mobiman/urdf/R1_PRO/meshes/right_arm_link2.STL" />
      </geometry>
    </collision>
  </link>
  <joint
    name="right_arm_joint2"
    type="revolute">
    <origin
      xyz="0 -0.1061 0"
      rpy="0 0 0" />
    <parent
      link="right_arm_link1" />
    <child
      link="right_arm_link2" />
    <axis
      xyz="0 0 1" />
    <limit
      lower="0"
      upper="3.2289"
      effort="40"
      velocity="20.944" />
  </joint>
  <link
    name="right_arm_link3">
    <inertial>
      <origin
        xyz="0.045115 -0.054616 0.00045613"
        rpy="0 0 0" />
      <mass
        value="0.818" />
      <inertia
        ixx="0.00060107"
        ixy="0.00022466"
        ixz="7.1148E-06"
        iyy="0.0013959"
        iyz="-9.7492E-06"
        izz="0.0015027" />
    </inertial>
    <visual>
      <origin
        xyz="0 0 0"
        rpy="0 0 0" />
      <geometry>
        <mesh
          filename="package://mobiman/urdf/R1_PRO/meshes/right_arm_link3.STL" />
      </geometry>
      <material
        name="">
        <color
          rgba="0.79216 0.81961 0.93333 1" />
      </material>
    </visual>
    <collision>
      <origin
        xyz="0 0 0"
        rpy="0 0 0" />
      <geometry>
        <mesh
          filename="package://mobiman/urdf/R1_PRO/meshes/right_arm_link3.STL" />
      </geometry>
    </collision>
  </link>
  <joint
    name="right_arm_joint3"
    type="revolute">
    <origin
      xyz="-0.34928 -0.020002 0"
      rpy="0 0 0" />
    <parent
      link="right_arm_link2" />
    <child
      link="right_arm_link3" />
    <axis
      xyz="0 0 1" />
    <limit
      lower="-3.3161"
      upper="0"
      effort="27"
      velocity="7.5398" />
  </joint>
  <link
    name="right_arm_link4">
    <inertial>
      <origin
        xyz="0.24285 -0.0023763 -3.4603E-07"
        rpy="0 0 0" />
      <mass
        value="0.816" />
      <inertia
        ixx="8.45E-05"
        ixy="8.2612E-07"
        ixz="2.2124E-09"
        iyy="0.00010174"
        iyz="5.3644E-09"
        izz="9.7044E-05" />
    </inertial>
    <visual>
      <origin
        xyz="0 0 0"
        rpy="0 0 0" />
      <geometry>
        <mesh
          filename="package://mobiman/urdf/R1_PRO/meshes/right_arm_link4.STL" />
      </geometry>
      <material
        name="">
        <color
          rgba="1 1 1 1" />
      </material>
    </visual>
    <collision>
      <origin
        xyz="0 0 0"
        rpy="0 0 0" />
      <geometry>
        <mesh
          filename="package://mobiman/urdf/R1_PRO/meshes/right_arm_link4.STL" />
      </geometry>
    </collision>
  </link>
  <joint
    name="right_arm_joint4"
    type="revolute">
    <origin
      xyz="0.02735 -0.069767 0"
      rpy="0 0 0" />
    <parent
      link="right_arm_link3" />
    <child
      link="right_arm_link4" />
    <axis
      xyz="1 0 0" />
    <limit
      lower="-2.8798"
      upper="2.8798"
      effort="7"
      velocity="25.133" />
  </joint>
  <link
    name="right_arm_link5">
    <inertial>
      <origin
        xyz="0.054309 -0.0041807 -3.8613E-06"
        rpy="0 0 0" />
      <mass
        value="0.801" />
      <inertia
        ixx="8.4E-05"
        ixy="-1.6234E-05"
        ixz="-7.4239E-08"
        iyy="9.8498E-05"
        iyz="-1.3874E-08"
        izz="0.00011333" />
    </inertial>
    <visual>
      <origin
        xyz="0 0 0"
        rpy="0 0 0" />
      <geometry>
        <mesh
          filename="package://mobiman/urdf/R1_PRO/meshes/right_arm_link5.STL" />
      </geometry>
      <material
        name="">
        <color
          rgba="1 1 1 1" />
      </material>
    </visual>
    <collision>
      <origin
        xyz="0 0 0"
        rpy="0 0 0" />
      <geometry>
        <mesh
          filename="package://mobiman/urdf/R1_PRO/meshes/right_arm_link5.STL" />
      </geometry>
    </collision>
  </link>
  <joint
    name="right_arm_joint5"
    type="revolute">
    <origin
      xyz="0.2463 0.00050106 0"
      rpy="0 0 0" />
    <parent
      link="right_arm_link4" />
    <child
      link="right_arm_link5" />
    <axis
      xyz="0 -1 0" />
    <limit
      lower="-1.6581"
      upper="1.6581"
      effort="7"
      velocity="25.133" />
  </joint>
  <link
    name="right_arm_link6">
    <inertial>
      <origin
        xyz="-0.031107 -1.3893E-07 -1.437E-07"
        rpy="0 0 0" />
      <mass
        value="0.465" />
      <inertia
        ixx="0.00017588"
        ixy="4.1789E-10"
        ixz="-5.3493E-10"
        iyy="9.8637E-05"
        iyz="-8.1856E-08"
        izz="0.00016512" />
    </inertial>
    <visual>
      <origin
        xyz="0 0 0"
        rpy="0 0 0" />
      <geometry>
        <mesh
          filename="package://mobiman/urdf/R1_PRO/meshes/right_arm_link6.STL" />
      </geometry>
      <material
        name="">
        <color
          rgba="0.82353 0.82353 1 1" />
      </material>
    </visual>
    <collision>
      <origin
        xyz="0 0 0"
        rpy="0 0 0" />
      <geometry>
        <mesh
          filename="package://mobiman/urdf/R1_PRO/meshes/right_arm_link6.STL" />
      </geometry>
    </collision>
  </link>
  <joint
    name="right_arm_joint6"
    type="revolute">
    <origin
      xyz="0.16215 -0.0004993 0"
      rpy="0 0 0" />
    <parent
      link="right_arm_link5" />
    <child
      link="right_arm_link6" />
    <axis
      xyz="1 0 0" />
    <limit
      lower="-2.8798"
      upper="2.8798"
      effort="7"
      velocity="25.133" />
  </joint>
  <link
    name="right_realsense_link">
    <inertial>
      <origin
        xyz="-0.017353 -0.022169 -0.0060171"
        rpy="0 0 0" />
      <mass
        value="0.25" />
      <inertia
        ixx="2.5513E-05"
        ixy="-1.2797E-06"
        ixz="1.4268E-06"
        iyy="6.965E-06"
        iyz="2.6612E-06"
        izz="2.3281E-05" />
    </inertial>
    <visual>
      <origin
        xyz="0 0 0"
        rpy="0 0 0" />
      <geometry>
        <mesh
          filename="package://mobiman/urdf/R1_PRO/meshes/right_realsense_link.STL" />
      </geometry>
      <material
        name="">
        <color
          rgba="0.8 0.8 0.8 1" />
      </material>
    </visual>
    <collision>
      <origin
        xyz="0 0 0"
        rpy="0 0 0" />
      <geometry>
        <mesh
          filename="package://mobiman/urdf/R1_PRO/meshes/right_realsense_link.STL" />
      </geometry>
    </collision>
  </link>
  <joint
    name="right_realsense_joint"
    type="fixed">
    <origin
      xyz="-0.00513786523359247 0.0021066154225865 0.0505493679929794"
      rpy="0.00858764076532865 0.436316268627042 0.00363356947600279" />
    <parent
      link="right_arm_link6" />
    <child
      link="right_realsense_link" />
    <axis
      xyz="0 0 0" />
  </joint>
  <link
    name="right_gripper_link1">
    <inertial>
      <origin
        xyz="-0.019589 -0.015114 0.0054225"
        rpy="0 0 0" />
      <mass
        value="0.057" />
      <inertia
        ixx="2.4057E-06"
        ixy="3.9897E-07"
        ixz="5.1206E-08"
        iyy="5.7108E-06"
        iyz="6.1948E-08"
        izz="6.4849E-06" />
    </inertial>
    <visual>
      <origin
        xyz="0 0 0"
        rpy="0 0 0" />
      <geometry>
        <mesh
          filename="package://mobiman/urdf/R1_PRO/meshes/right_gripper_link1.STL" />
      </geometry>
      <material
        name="">
        <color
          rgba="0.82353 0.82353 1 1" />
      </material>
    </visual>
    <collision>
      <origin
        xyz="0 0 0"
        rpy="0 0 0" />
      <geometry>
        <mesh
          filename="package://mobiman/urdf/R1_PRO/meshes/right_gripper_link1.STL" />
      </geometry>
    </collision>
  </link>
  <joint
    name="right_gripper_joint1"
    type="prismatic">
    <origin
      xyz="0.03689 0.013453 0.00012067"
      rpy="0 0 0" />
    <parent
      link="right_arm_link6" />
    <child
      link="right_gripper_link1" />
    <axis
      xyz="0 1 0" />
    <limit
      lower="0"
      upper="0.05"
      effort="100"
      velocity="0.25" />
  </joint>
  <link
    name="right_gripper_link2">
    <inertial>
      <origin
        xyz="-0.01959 0.015114 -0.0054226"
        rpy="0 0 0" />
      <mass
        value="0.057" />
      <inertia
        ixx="2.4057E-06"
        ixy="-3.99E-07"
        ixz="-5.1222E-08"
        iyy="5.7108E-06"
        iyz="6.1946E-08"
        izz="6.4849E-06" />
    </inertial>
    <visual>
      <origin
        xyz="0 0 0"
        rpy="0 0 0" />
      <geometry>
        <mesh
          filename="package://mobiman/urdf/R1_PRO/meshes/right_gripper_link2.STL" />
      </geometry>
      <material
        name="">
        <color
          rgba="0.82353 0.82353 1 1" />
      </material>
    </visual>
    <collision>
      <origin
        xyz="0 0 0"
        rpy="0 0 0" />
      <geometry>
        <mesh
          filename="package://mobiman/urdf/R1_PRO/meshes/right_gripper_link2.STL" />
      </geometry>
    </collision>
  </link>
  <joint
    name="right_gripper_joint2"
    type="prismatic">
    <origin
      xyz="0.03689 -0.013453 -0.00012053"
      rpy="0 0 0" />
    <parent
      link="right_arm_link6" />
    <child
      link="right_gripper_link2" />
    <axis
      xyz="0 -1 0" />
    <limit
      lower="0"
      upper="0.05"
      effort="100"
      velocity="0.25" />
  </joint>
</robot>